Workbook

Sheet Tissues
A1: tissue | B1: subtissue | C1: comment | D1: mass | E1: sem | F1: groups | G1: front line organ | H1: for_final_table | I1: child_10y | J1: woman | K1: man
A2: Blood | D2: 5241 | F2: blood | H2: Blood | I2: 2616 | J2: 4251 | K2: 5500
A3: Red marrow | D3: 1500 | F3: marrow | H3: Bone Marrow | I3: 630 | J3: 900 | K3: 1170
A4: Lymph nodes | D4: 250 | F4: lymph system | H4: Lymph system | I4: 99 | J4: 185 | K4: 225
A5: Lymph vessels | D5: 450 | F5: connective | H5: Lymph system | I5: 221 | J5: 415 | K5: 505
A6: Spleen | D6: 150 | E6: 20 | F6: lymph system | H6: Lymph system | I6: 80 | J6: 130 | K6: 150
A7: Thymus | D7: 25 | F7: lymph system | H7: Lymph system | I7: 40 | J7: 25 | K7: 20
A8: Tonsils | C8: (2 palatine) | D8: 4 | F8: lymph system | H8: Lymph system | I8: 3 | J8: 3 | K8: 3
A9: Liver | D9: 1800 | F9: epithelial organ | H9: Liver | I9: 830 | J9: 1400 | K9: 1800
A10: Esophagus | D10: 40 | F10: epithelial organ | G10: 1 | H10: GI | I10: 18 | J10: 35 | K10: 40
A11: Stomach | B11: Epithelium | C11: assuming 1/3 | D11: 50 | F11: epithelial organ | G11: 1 | H11: GI | I11: 28 | J11: 47 | K11: 50
A12: Stomach | B12: LP | C12: assuming 1/3 | D12: 50 | F12: epithelial organ | G12: 1 | H12: GI | I12: 28 | J12: 47 | K12: 50
A13: Stomach | B13: Submucosa + Proper muscle | C13: assuming 1/3 | D13: 50 | F13: epithelial organ | G13: 1 | H13: GI | I13: 28 | J13: 47 | K13: 50
A14: SI | B14: Epithelium | D14: 165 | E14: 23 | F14: epithelial organ | G14: 1 | H14: GI | I14: 99 | J14: 161 | K14: 174
A15: SI | B15: LP | D15: 134 | E15: 19 | F15: epithelial organ | G15: 1 | H15: GI | I15: 80 | J15: 131 | K15: 141
A16: SI | B16: Submucosa + Proper muscle | D16: 317 | E16: 130 | F16: epithelial organ | G16: 1 | H16: GI | I16: 190 | J16: 309 | K16: 334
A17: Colon | B17: Epithelium | C17: including rectum | D17: 75 | E17: 16 | F17: epithelial organ | G17: 1 | H17: GI | I17: 40 | J17: 68 | K17: 70
A18: Colon | B18: LP | C18: including rectum | D18: 60 | E18: 13 | F18: epithelial organ | G18: 1 | H18: GI | I18: 32 | J18: 55 | K18: 56
A19: Colon | B19: Submucosa + Proper muscle | C19: including rectum | D19: 260 | E19: 90 | F19: epithelial organ | G19: 1 | H19: GI | I19: 138 | J19: 237 | K19: 244
A20: Lungs | B20: Parenchyma | D20: 540 | F20: epithelial organ | G20: 1 | H20: Lungs | I20: 197 | J20: 395 | K20: 470
A21: Lungs | B21: Pulmonary blood | C21: (plus arterial and venous blood) | D21: =1000-D20-D29 -> 425 | F21: epithelial organ | G21: 1 | H21: Lungs | I21: 290 | J21: 530 | K21: 700
A22: Kidneys | B22: Renal cortex | C22: 2 | D22: =310*70% -> 217 | F22: epithelial organ | H22: Others | I22: 133 | J22: 203 | K22: 228
A23: Kidneys | B23: Medulla | D23: =310*25% -> 77.5 | F23: epithelial organ | H23: Others | I23: 47 | J23: 72 | K23: 82
A24: Pancreas | D24: 100 | F24: epithelial organ | H24: Others | I24: 60 | J24: 120 | K24: 140
A25: Skin | B25: Epidermis | D25: 100 | F25: epithelial organ | G25: 1 | H25: Skin | I25: 56 | J25: 85 | K25: 120
A26: Skin | B26: Dermis | D26: 2500 | F26: epithelial organ | G26: 1 | H26: Skin | I26: 764 | J26: 2215 | K26: 3180
A27: Salivary glands | C27: (3 prs.) | D27: 85 | F27: epithelial organ | H27: Others | I27: 44 | J27: 70 | K27: 85
A28: Urinary bladder | D28: 45 | F28: epithelial organ | H28: Others | I28: 25 | J28: 40 | K28: 50
A29: Testes | C29: 2 | D29: 35 | F29: epithelial organ | H29: Others | I29: 2 | J29: 0 | K29: 35
A30: Bronchial tree | D30: 30 | F30: epithelial organ | G30: 1 | H30: Lungs | I30: 13.15 | J30: 24.66 | K30: 30
A31: Larynx | D31: 28 | F31: epithelial organ | G31: 1 | H31: Lungs | I31: 12 | J31: 19 | K31: 28
A32: Breasts | C32: 2 | D32: 26 | F32: epithelial organ | H32: Others | I32: 15 | J32: 500 | K32: 25
A33: Thyroid | D33: 20 | F33: epithelial organ | H33: Others | I33: 7.9 | J33: 17 | K33: 20
A34: Prostate gland | D34: 16 | F34: epithelial organ | H34: Others | I34: 1.6 | J34: 0 | K34: 17
A35: Ureters | C35: 2 | D35: 16 | F35: epithelial organ | H35: Others | I35: 7 | J35: 15 | K35: 16
A36: Adrenal glands | C36: 2 | D36: 14 | F36: epithelial organ | H36: Others | I36: 7 | J36: 13 | K36: 14
A37: Gallbladder | D37: 10 | F37: epithelial organ | H37: Others | I37: 4.4 | J37: 8 | K37: 10
A38: Trachea | D38: 10 | F38: epithelial organ | G38: 1 | H38: Lungs | I38: 4.5 | J38: 8 | K38: 10
A39: Urethra | D39: 10 | F39: epithelial organ | H39: Others | I39: 3 | J39: 3 | K39: 10
A40: Pituitary gland | D40: 0.6 | F40: epithelial organ | H40: Others | I40: 0.35 | J40: 0.6 | K40: 0.6
...

Sheet Myeloid_cells
A1: Source | B1: cell_type | C1: tissue | D1: subtissue | E1: location | F1: specie | G1: population | H1: method | I1: original area [mu^2] | J1: thickness [mu] | K1: cells_per_area | L1: sem_cells_area | M1: ratio_of_target_to_anchor | N1: sem_ratio_of_target_to_anchor | O1: anchor_cells | P1: anchor_cells_sem | Q1: anchor_density | R1: anchor_density_sem | S1: total_target_cells | T1: total_target_cells_sem | U1: relevant_tissue_volume | V1: relevant_tissue_volume_sem | W1: target_cells_density_per_g | X1: target_cells_density_sem | Y1: comment
A2: Gates 1961 | B2: Kupffer cells | C2: Liver | F2: human | G2: healthy tissues from patients | H2: histology | W2: 20000000 | X2: 500000 | Y2: The same derivation we did in Sender & Milo 2021. combining data regarding the fraction of Kupffer cells compared to stallete cells
A3: Stone et al. 1992 | B3: Alveolar macrophages | C3: Lungs | D3: Parenchyma | F3: human | G3: healthy tissues from patients | H3: histology | S3: 12000000000 | T3: 4000000000 | U3: 500 | V3: 100 | W3: 24000000 | X3: 9000000 | Y3: total volume of 8.2 cm^3 in alveolar macrophages
A4: Crapo et al. 1982 | B4: Alveolar macrophages | C4: Lungs | D4: Parenchyma | F4: human | G4: healthy tissues deceased | H4: histology | S4: 46000000000 | T4: 10000000000 | U4: 500 | V4: 100 | W4: 92000000 | X4: 34000000
A5: Ogawa et al. 2000 | B5: Macrophage | C5: Red marrow | F5: human | G5: healthy tissues deceased | H5: histology | M5: 0.083 | N5: 0.017 | O5: 1000000000000 | P5: 400000000000 | S5: 80000000000 | T5: 30000000000 | U5: 1170 | W5: 70000000 | X5: 30000000 | Y5: our of total BM cellularity
A6: Lee et al. 1988 | B6: Macrophage | C6: Red marrow | E6: Blood islands | F6: human | G6: healthy tissues deceased | H6: histology | M6: 0.067 | N6: 0.03 | O6: 600000000000 | S6: 40000000000 | T6: 20000000000 | U6: 1170 | W6: 30000000 | X6: 10000000 | Y6: range of 5-30 erthroid cells per island (one macrophages)
A7: Lyck et. al.2019 | B7: Microglia | C7: Brain | F7: human | G7: healthy tissues deceased | H7: Immunohistochemistry | W7: 8000000 | X7: 600000 | Y7: calculated the density from the number estimates and the volume estimates (per donor)
A8: Pelvig et al. 2008 | B8: Microglia | C8: Brain | F8: human | G8: healthy | H8: histology | M8: 0.06 | N8: 0.01 | O8: 90000000000 | P8: 10000000000 | S8: 5000000000 | T8: 1000000000 | U8: 1450 | V8: 100 | W8: 8000000 | X8: 600000 | Y8: used their fraction as their total numbers seems low compared to Azvedo's
A9: Morgan-Bathke et al. 2017 | B9: Macrophage | C9: Adipose tissue | E9: abdominal, femoral | F9: human | G9: obease (BMI=32) | H9: histology | W9: 130000 | X9: 12000 | Y9: values taken from the CD68+ population (macrophages)
A10: Morgan-Bathke et al. 2017 | B10: Macrophage | C10: Adipose tissue | E10: abdominal, femoral | F10: human | G10: obease (BMI=32) | H10: histology | M10: 0.154 | N10: 0.016 | O10: 50000000000 | P10: 20000000000 | S10: 8000000000 | T10: 4000000000 | U10: 15000 | W10: 500000 | X10: 200000 | Y10: same paper, but given as ratio to adipocytes
A11: Halme et al. 1984 | B11: Macrophage | C11: Connective tissue | E11: Peritoneal liquid | F11: human | G11: women | H11: FACS | U11: 10 | V11: 5 | W11: 2000000 | X11: 400000 | Y11: changes with the phases of the menstrual cycle
A12: McGovern et al. 2014 | B12: Demal macrophages | C12: Skin | E12: whole skin | F12: human | G12: healthy women | H12: FACS | M12: 0.056 | N12: 0.009 | O12: 19000000000 | P12: 10000000000 | S12: 1100000000 | T12: 580000000 | U12: 555 | W12: 1900000 | X12: 1100000 | Y12: reference are dermal fibroblast
A13: McGovern et al. 2014 | B13: CD1a+ Dendritic cells | C13: Skin | E13: whole skin | F13: human | G13: healthy women | H13: FACS | M13: 0.059 | N13: 0.0065 | O13: 19000000000 | P13: 10000000000 | S13: 1100000000 | T13: 600000000 | U13: 555 | W13: 2000000 | X13: 1100000 | Y13: reference are dermal fibroblast
A14: Bauer et al. 2001 | B14: Langerhans cells | C14: Skin | D14: Epidermis | F14: human | G14: healthy women | H14: histology | W14: 23000000 | X14: 5000000 | Y14: calcuated from areal density and thickness of epidermis measured as 60 micron
A15: Singh et al. 2019 | B15: Macrophage | C15: Kidneys | D15: Renal cortex | F15: human | G15: tumor-remote regions | H15: Multiplex | I15: 1000000 | J15: 0 | K15: 7 | L15: 0.4 | W15: 700000 | X15: 40000 | Y15: calcuated from the density of all cells (translated from areal to volume) and the fraction of macrophages
A16: Singh et al. 2019 | B16: Macrophage | C16: Kidneys | D16: Medulla | F16: human | G16: tumor-remote regions | H16: Multiplex | I16: 1000000 | J16: 0 | K16: 59.5 | L16: 3.4 | W16: 6000000 | X16: 340000 | Y16: calcuated from the density of all cells (translated from areal to volume) and the fraction of macrophages
A17: Schmidt et al. 1993 | B17: Macrophage | C17: Skeletal Muscles | E17: adbominal | F17: human | G17: healthy | H17: histology | I17: 1000000 | J17: 8 | K17: 13 | L17: 3.1 | W17: 720000 | X17: 170000 | Y17: taken only the meausrments from skeletal muscles and not the eye muscles
A18: Azzawi et al. 1997 | B18: Macrophage | C18: Heart | F18: human | G18: healthy tissues deceased | H18: histology | I18: 100000 | J18: 3 | K18: 1 | L18: 0.5 | W18: 770000 | X18: 380000 | Y18: given per HPF without area size, asumed similar to previous paper
A19: Gualdron-Lopez et al. 2021 | B19: Macrophage | C19: Spleen | F19: human | G19: transplantation donors | H19: FACS | M19: 0.001 | N19: 0 | Q19: 1400000000 | W19: 1400000 | X19: 410000 | Y19: relative to all leukocytes (almost everything but RBCs) in the spleen, used the density found in the lymphocytes analysis
A20: Gualdron-Lopez et al. 2021 | B20: Dendritic cells | C20: Spleen | F20: human | G20: transplantation donors | H20: FACS | M20: 0.0033 | N20: 0.0011 | Q20: 1400000000 | W20: 4400000 | X20: 1500000 | Y20: relative to all leukocytes (almost everything but RBCs) in the spleen, used the density found in the lymphocytes analysis
A21: Nagashima et al. 1996 | B21: Lamina propria macrophages | C21: Stomach | D21: LP | F21: human | G21: healthy tissues from patients | H21: histology | M21: 0.01 | N21: 0.004 | O21: 20000000000 | P21: 4000000000 | S21: 200000000 | T21: 80000000 | U21: 50 | V21: 20 | W21: 3000000 | X21: 2000000 | Y21: data given as ratio to the epithelial cells above
A22: Nagashima et al. 1996 | B22: Lamina propria macrophages | C22: SI | D22: LP | E22: duodenum | F22: human | G22: healthy tissues from patients | H22: histology | M22: 0.009 | N22: 0.001 | O22: 7000000000 | P22: 2000000000 | S22: 70000000 | T22: 20000000 | U22: 8 | V22: 2 | W22: 8000000 | X22: 3000000 | Y22: data given as ratio to the epithelial cells above
A23: Nagashima et al. 1996 | B23: Lamina propria macrophages | C23: SI | D23: LP | E23: ileum, jejunum | F23: human | G23: healthy tissues from patients | H23: histology | M23: 0.009 | N23: 0.002 | O23: 100000000000 | P23: 30000000000 | S23: 1000000000 | T23: 400000000 | U23: 120 | V23: 13 | W23: 8000000 | X23: 3000000 | Y23: data given as ratio to the epithelial cells above
A24: Nagashima et al. 1996 | B24: Lamina propria macrophages | C24: Colon | D24: LP | E24: Colon | F24: human | G24: healthy tissues from patients | H24: histology | M24: 0.07 | N24: 0.001 | O24: 50000000000 | P24: 20000000000 | S24: 4000000000 | T24: 2000000000 | U24: 51 | V24: 12 | W24: 70000000 | X24: 30000000
A25: Nagashima et al. 1996 | B25: Lamina propria macrophages | C25: Colon | D25: LP | E25: Rectum | F25: human | G25: healthy tissues from patients | H25: histology | M25: 0.06 | N25: 0.006 | O25: 7000000000 | P25: 3000000000 | S25: 400000000 | T25: 200000000 | U25: 7 | V25: 1 | W25: 60000000 | X25: 30000000
A26: Van Furth & Dulk | B26: Macrophage | C26: Spleen | F26: mouse | M26: 0.025 | N26: 0.0075 | Q26: 1500000000 | R26: 300000000 | W26: 40000000 | X26: 10000000
A27: Greer et al. 2004 | B27: Monocyte | C27: Lymph nodes | F27: mouse | M27: 0.004 | N27: 0.001 | Q27: 1000000000 | W27: 4000000 | X27: =Q27*N27 -> 1000000 | Y27: density of LN cells taken from non-human
A28: Kumar et al. 2015 | B28: Macrophage | C28: Lymph nodes | F28: mouse | G28: healthy | H28: FACS | M28: 0.01 | N28: 0.001 | Q28: 1000000000 | W28: 10000000 | X28: =Q28*N28 -> 1000000
A29: Kumar et al. 2015 | B29: Dendritic cells | C29: Lymph nodes | F29: mouse | G29: healthy | H29: FACS | M29: 0.006 | N29: 0.001 | Q29: 1000000000 | W29: 6000000 | X29: =Q29*N29 -> 1000000
A30: Lee et al. 1985 | B30: Macrophage | C30: Bone marrow | F30: mouse | G30: healthy | H30: Absorption Indirect Binding Assay | W30: 60000000 | X30: 6000000
A31: Lee et al. 1985 | B31: Macrophage | C31: Lungs | F31: mouse | G31: healthy | H31: Absorption Indirect Binding Assay | W31: 10000000 | X31: 2000000
A32: Lee et al. 1985 | B32: Macrophage | C32: Kidneys | D32: Renal cortex | F32: mouse | G32: healthy | H32: Absorption Indirect Binding Assay | W32: 20000000 | X32: 5000000
A33: Lee et al. 1985 | B33: Macrophage | C33: Testes | F33: mouse | G33: healthy | H33: Absorption Indirect Binding Assay | W33: 10000000 | X33: 2000000
A34: Lee et al. 1985 | B34: Macrophage | C34: Urinary bladder | F34: mouse | G34: healthy | H34: Absorption Indirect Binding Assay | W34: 3000000 | X34: 0
A35: Lee et al. 1985 | B35: Macrophage | C35: Adrenal glands | F35: mouse | G35: healthy | H35: Absorption Indirect Binding Assay | W35: 10000000 | X35: 3000000
A36: Lee et al. 1985 | B36: Macrophage | C36: Stomach | D36: LP | F36: mouse | G36: healthy | H36: Absorption Indirect Binding Assay | W36: 10000000 | X36: 3000000
A37: Lee et al. 1985 | B37: Macrophage | C37: SI | D37: LP | F37: mouse | G37: healthy | H37: Absorption Indirect Binding Assay | W37: 10000000 | X37: 3000000
A38: Lee et al. 1985 | B38: Macrophage | C38: Colon | D38: LP | F38: mouse | G38: healthy | H38: Absorption Indirect Binding Assay | W38: 20000000 | X38: 3000000
A39: Lee et al. 1985 | B39: Macrophage | C39: Lymph nodes | E39: Cervical | F39: mouse | G39: healthy | H39: Absorption Indirect Binding Assay | W39: 20000000 | X39: 5000000
A40: Lee et al. 1985 | B40: Macrophage | C40: Lymph nodes | E40: Mesenteric | F40: mouse | G40: healthy | H40: Absorption Indirect Binding Assay | W40: 30000000 | X40: 6000000
...

Sheet Granulocytes
A1: Source | B1: cell_type | C1: tissue | D1: subtissue | E1: location | F1: specie | G1: population | H1: method | I1: original area [mu^2] | J1: thickness [mu] | K1: cells_per_area | L1: sem_cells_area | M1: ratio_of_target_to_anchor | N1: sem_ratio_of_target_to_anchor | O1: anchor_cells | P1: anchor_cells_sem | Q1: anchor_density | R1: anchor_density_sem | S1: total_target_cells | T1: total_target_cells_sem | U1: relevant_tissue_volume | V1: relevant_tissue_volume_sem | W1: target_cells_density_per_g | X1: target_cells_density_sem | Y1: comment
A2: Sender & Milo 2021 | B2: Neutrophil | C2: Blood | F2: human | G2: healthy | H2: integration of previous studies | S2: 21000000000 | T2: 1000000000 | U2: 5200 | W2: 4000000 | X2: 190000
A3: Sender & Milo 2021 | B3: Neutrophil | C3: Bone Marrow | D3: mitotic pool | F3: human | G3: healthy | H3: integration of previous studies | S3: 180000000000 | T3: 30000000000 | U3: 1170 | W3: 150000000 | X3: 26000000
A4: Sender & Milo 2021 | B4: Neutrophil | C4: Bone Marrow | D4: post-mitotic pool | F4: human | G4: healthy | H4: integration of previous studies | S4: 420000000000 | T4: 60000000000 | U4: 1170 | W4: 360000000 | X4: 51000000
A5: Sender & Milo 2021 | B5: Neutrophil | C5: other | E5: marginal pool | F5: human | G5: healthy | H5: integration of previous studies | S5: 21000000000 | T5: 1000000000
A6: Dhesi et al. 1984 | B6: Neutrophil | C6: Colon | D6: LP | F6: human | G6: healthy | H6: histology | S6: 250000000 | T6: 190000000 | U6: 186 | V6: 22 | W6: 1300000 | X6: 1000000 | Y6: estimates based on the density of plasma cells from other studies, using the ratio of neurtrophils to plasma cells from Dhesi
A7: Gualdron-Lopez et al. 2021 | B7: Neutrophil | C7: Spleen | E7: red pulp | F7: human | G7: transplantation donors | H7: FACS | M7: 0.179 | N7: 0.035 | P7: 2000000000 | Q7: 100000000 | S7: 40000000000 | T7: 9900000000 | U7: 150 | V7: 20 | W7: 300000000 | X7: 55000000 | Y7: fraction of leukocytes (almost everything but RBCs)
A8: Liang et al. 2015 | B8: Neutrophil | C8: Skeletal Muscles | F8: macaques | H8: FACS | M8: 0.002 | N8: 0.0002 | P8: 700000 | Q8: 100000 | S8: 40000000 | T8: 7900000 | U8: 28500 | V8: 3000 | W8: 1000 | X8: 200 | Y8: fraction out of live cells
A9: Lok et al. 2019 | B9: Neutrophil | C9: Lymph nodes | F9: human | H9: FACS | M9: 0.0081 | N9: 0.0038 | P9: 650000000 | Q9: 80000000 | S9: 1200000000 | T9: 590000000 | U9: 225 | V9: 30 | W9: 5300000 | X9: 3000000 | Y9: fraction out of live cells, averaged over three LN
A10: Banat et al. 2015 | B10: Neutrophil | C10: Lungs | D10: Parenchyma | F10: human | G10: healthy | H10: histology | M10: 0.0081 | N10: 0.001 | O10: 300000000000 | S10: 2000000000 | T10: 1200000000 | U10: =Tissues!$D$20 -> 540 | W10: =S10/U10 -> 3703703.7 | X10: =T10/S10*W10 -> 2222222.2 | Y10: fraction of cells, total cells taken from Travaglini et al. 2020
A11: Donohue et al. 1958 + Harrison 1962 + Greer 2004 | B11: Eosinophil | C11: Bone Marrow | D11: mitotic pool | F11: human | H11: integration | M11: 0.01 | N11: 0.004 | O11: 1000000000000 | P11: 350000000000 | S11: 9800000000 | T11: 5200000000 | U11: 1170 | W11: 8300000 | X11: 4500000 | Y11: the anchor is all nucleated cells in the BM
A12: Donohue et al. 1958 + Harrison 1962 + Greer 2004 | B12: Eosinophil | C12: Bone Marrow | D12: non mitotic pool | F12: human | H12: integration | M12: 0.021 | N12: 0.007 | O12: 1000000000000 | P12: 350000000000 | S12: 22000000000 | T12: 11000000000 | U12: 1170 | W12: 19000000 | X12: 9000000 | Y12: the anchor is all nucleated cells in the BM
A13: Walle & Parawaresch 1979 | B13: Eosinophil | C13: Bone Marrow | D13: non mitotic pool | F13: human | G13: old cancer patients | H13: labeling study + model | S13: 9600000000 | T13: 2800000000 | U13: 1170 | W13: 8200000 | X13: 2400000
A14: Walle & Parawaresch 1979 | B14: Eosinophil | C14: Blood | F14: human | H14: Blood count | S14: 930000000 | T14: 200000000 | U14: 5200 | V14: 500 | W14: 180000 | X14: 33000
A15: Sevitt 1955 | B15: Eosinophil | C15: Spleen | F15: human | S15: 2300000000 | T15: 780000000 | U15: 150 | V15: 20 | W15: 16000000 | X15: 4800000
A16: Thorsby et al. 2000 | B16: Eosinophil | C16: Thymus | F16: rat | H16: FACS | M16: 0.002 | Q16: 1500000000 | R16: 100000000 | W16: 3000000 | X16: 200000 | Y16: the anchor is total thymus cells. according to MIBI-TOF
A17: Bischoff et al. 1996 | B17: Eosinophil | C17: Colon | D17: LP | E17: lower GI | F17: human | G17: control | H17: histology | I17: 1000000 | J17: 5 | K17: 258 | L17: 26 | W17: 20000000 | X17: 2000000
A18: DeBrosse et al. 2006 | B18: Eosinophil | C18: Stomach | D18: LP | F18: human | G18: children around age 10 | H18: histology | I18: 280000 | J18: 5 | K18: 2 | L18: 1.5 | W18: 500000 | X18: 400000
A19: DeBrosse et al. 2007 | B19: Eosinophil | C19: SI | D19: LP | E19: Duodenum | F19: human | G19: children around age 10 | H19: histology | I19: 280000 | J19: 5 | K19: 9.6 | L19: 5.3 | W19: 2000000 | X19: 1000000
A20: DeBrosse et al. 2008 | B20: Eosinophil | C20: SI | D20: LP | E20: Ileum | F20: human | G20: children around age 10 | H20: histology | I20: 280000 | J20: 5 | K20: 12.4 | L20: 5.4 | W20: 3000000 | X20: 1000000
A21: DeBrosse et al. 2009 | B21: Eosinophil | C21: Colon | D21: LP | E21: Colon | F21: human | G21: children around age 10 | H21: histology | I21: 280000 | J21: 5 | K21: 18.3 | L21: 7.5 | W21: 4000000 | X21: 2000000
A22: DeBrosse et al. 2010 | B22: Eosinophil | C22: Colon | D22: LP | E22: Rectum | F22: human | G22: children around age 10 | H22: histology | I22: 280000 | J22: 5 | K22: 8.3 | L22: 5.9 | W22: 2000000 | X22: 1000000
A23: Travaglini et al. 2020 | B23: Eosinophil | C23: Lungs | D23: Parenchyma | F23: human | H23: integration of histology | M23: 0.25 | N23: 0.1 | O23: 4600000000 | S23: 1200000000 | T23: 460000000 | U23: =Tissues!$D$20 -> 540 | W23: =S23/U23 -> 2222222.2 | X23: =T23/S23*W23 -> 851851.85 | Y23: based on Finkelstein et al. 1995 and Banat et al. 2015, anchor is all PMN, assuming neutriphil are more than half based on the previous study
A24: Kato et al., 1998 | B24: Eosinophil | C24: other | F24: human | W24: 0 | X24: 0
A25: Saad, 2011 | B25: Mast cell | C25: Colon | D25: LP | F25: human | G25: children | H25: histology of bioposies | I25: 300000 | J25: 5 | K25: 16 | L25: 7 | W25: 4000000 | X25: 2000000 | Y25: two orders of magnitude more than in the epithleium
A26: Bischoff et al. 1996 | B26: Mast cell | C26: Colon | D26: LP | F26: human | G26: control patients | H26: histology of bioposies | I26: 1000000 | J26: 5 | K26: 206 | L26: 18 | W26: 10000000 | X26: 1000000
A27: Bischoff et al. 1996 | B27: Mast cell | C27: SI | D27: LP | F27: human | G27: control patients | H27: histology of bioposies | I27: 1000000 | J27: 5 | K27: 206 | L27: 18 | W27: 10000000 | X27: 1000000
A28: Travaglini et al. 2020 | B28: Mast cell | C28: Lungs | D28: Parenchyma | E28: alveolar parenchyma | F28: human | H28: derived from fraction of cells in histology | S28: 3000000000 | U28: 500 | W28: 6000000
A29: Yang et al. 2018 | B29: Mast cell | C29: Skin | D29: Dermis | E29: close to various locations (hair folliceles, nerve, muscle, adipose) | F29: rat | H29: histology of bioposies | I29: 100000 | J29: 5 | K29: 11 | L29: 2.5 | W29: 7000000 | X29: 2000000 | Y29: averaged over different locations
A30: Rathod et al. 2018 | B30: Mast cell | C30: Connective tissue | E30: Gums | F30: human | G30: healthy control | H30: histology of bioposies | I30: 1000000 | J30: 5 | K30: 98 | L30: 6 | W30: 7000000 | X30: 400000
A31: Carrol et al. 2002 | B31: Mast cell | C31: Trachea | E31: cartilaginous airways | F31: human | G31: healthy control | H31: histology of bioposies | I31: 1000000 | J31: 5 | K31: 27 | L31: 9 | W31: 2000000 | X31: 600000
A32: Carrol et al. 2002 | B32: Mast cell | C32: Bronchial tree | E32: membranous airways | F32: human | G32: healthy control | H32: histology of bioposies | I32: 1000000 | J32: 5 | K32: 155 | L32: 21 | W32: 10000000 | X32: 1000000
A33: Anderson et al. 2008 | B33: Mast cell | C33: Trachea | E33: central airways | F33: human | G33: healthy | H33: histology of bioposies | I33: 1000000 | J33: 3 | K33: 160 | L33: 48 | W33: 10000000 | X33: 4000000
A34: Anderson et al. 2008 | B34: Mast cell | C34: Bronchial tree | E34: small airways | F34: human | G34: healthy | H34: histology of bioposies | I34: 1000000 | J34: 3 | K34: 307 | L34: 20 | W34: 20000000 | X34: 2000000
A35: Anderson et al. 2008 | B35: Mast cell | C35: Lungs | D35: Parenchyma | E35: alveolar parenchyma | F35: human | G35: healthy | H35: histology of bioposies | I35: 1000000 | J35: 3 | K35: 398 | L35: 73 | W35: 30000000 | X35: 6000000
A36: Anderson et al. 2008 | B36: Mast cell | C36: Lungs | D36: Pulmonary blood | E36: perivascular tissue | F36: human | G36: healthy | H36: histology of bioposies | I36: 1000000 | J36: 3 | K36: 227 | L36: 61 | W36: 20000000 | X36: 5000000
A37: Jiang et al. 2002 | B37: Mast cell | C37: Stomach | D37: LP | E37: Gastric carcinoma | F37: human | G37: cancer patients | H37: histology of bioposies | I37: 30000 | J37: 3.5 | K37: 21 | W37: 50000000 | Y37: only results are given relative to a threshold to 21/0.03 mm2, we use this as some reference
A38: Legere et al. 2020 | B38: Mast cell | C38: Heart | E38: atria | F38: human | G38: cardiac surgery patients | H38: histology of bioposies | I38: 1000000 | J38: 5 | K38: 7 | L38: 5 | W38: 500000 | X38: 300000 | Y38: thickness not given. assumed 5 mu
A39: Craig et al. 1986 | B39: Mast cell | C39: Skin | D39: Dermis | E39: Keliod | F39: human | H39: histology of bioposies | W39: 3000000 | X39: 100000 | Y39: given as cells per mm^3 and tranformed by us to cm^3
A40: Craig et al. 1986 | B40: Mast cell | C40: Bronchial tree | E40: epithelial | F40: human | H40: histology of bioposies | W40: 8000000 | X40: 5000000 | Y40: given as cells per mm^3 and tranformed by us to cm^3
...

Sheet Lymphocytes
A1: Source | B1: cell_type | C1: tissue | D1: subtissue | E1: location | F1: specie | G1: population | H1: method | I1: original area [mu^2] | J1: thickness [mu] | K1: cells_per_area | L1: sem_cells_area | M1: ratio_of_target_to_anchor | N1: sem_ratio_of_target_to_anchor | O1: anchor_cells | P1: anchor_cells_sem | Q1: anchor_density | R1: anchor_density_sem | S1: total_target_cells | T1: total_target_cells_sem | U1: relevant_tissue_volume | V1: relevant_tissue_volume_sem | W1: target_cells_density_per_g | X1: target_cells_density_sem | Y1: comment
A2: Apoil et al. 2017 | B2: T cells | C2: Blood | F2: human | H2: Blood count | W2: =1000*1433 -> 1433000 | X2: 55.220589 | Y2: density==1, ml->g
A3: Apoil et al. 2017 | B3: B cells | C3: Blood | F3: human | H3: Blood count | W3: =1000*245 -> 245000 | X3: 13.927317 | Y3: density==1, ml->g
A4: Apoil et al. 2017 | B4: NK cells | C4: Blood | F4: human | H4: Blood count | W4: =1000*284 -> 284000 | X4: 18.569756 | Y4: density==1, ml->g
A5: Apoil et al. 2017 | B5: Plasma cells | C5: Blood | F5: human | H5: Blood count | W5: =1000*3.4 -> 3400 | X5: 0.47646083 | Y5: plasmablast, density==1, ml->g
A6: Donohue et al. 1958 | B6: Lymphocytes | C6: Red marrow | F6: human | H6: Fe59 method | M6: =4.6% -> 0.046 | O6: =18*10^9*70 -> 1260000000000 | P6: 400000000000 | S6: =M6*O6 -> 57960000000 | T6: =M6*P6 -> 18400000000 | U6: 1170 | W6: =S6/U6 -> 49538462 | X6: =T6/S6*W6 -> 15726496
A7: Harrison 1962 | B7: Lymphocytes | C7: Red marrow | F7: human | H7: Fe59 method | M7: =(3.4%+0.7%)/(1-3.6%) -> 0.04253112 | O7: =AVERAGE(10.4,11.1)*10^9*70 -> 752500000000 | P7: =STDEV(10.4,11.1)*10^9*70 -> 34648232278 | S7: =M7*O7 -> 32004668050 | T7: =M7*P7 -> 1473628136 | U7: 1170 | W7: =S7/U7 -> 27354417 | X7: =T7/S7*W7 -> 1259511.2
A8: Five studies | B8: T cells | C8: Red marrow | F8: human | H8: Biopsies and cryostat sections | M8: =Lymph_subgroups_and_details!N5 -> 0.53986472 | N8: =Lymph_subgroups_and_details!M5 -> 0.094733285 | Q8: =AVERAGE($W$6:$W$7) -> 38446439 | R8: =sqrt(sumsq(stdev($W$6:$W$7), average($X$6:$X$7))) -> 17838078 | U8: 1170 | W8: =Q8*M8 -> 20755876 | X8: =sqrt(sumsq(M8*R8,N8*Q8)) -> 10295877 | Y8: see details in the subgroup and details tab
A9: Five studies | B9: B cells | C9: Red marrow | F9: human | H9: Biopsies and cryostat sections | M9: =Lymph_subgroups_and_details!N6 -> 0.37432658 | N9: =Lymph_subgroups_and_details!M6 -> 0.064498043 | Q9: =AVERAGE($W$6:$W$7) -> 38446439 | R9: =sqrt(sumsq(stdev($W$6:$W$7), average($X$6:$X$7))) -> 17838078 | U9: 1170 | W9: =Q9*M9 -> 14391524 | X9: =sqrt(sumsq(M9*R9,N9*Q9)) -> 7122843.7 | Y9: see details in the subgroup and details tab
A10: Five studies | B10: NK cells | C10: Red marrow | F10: human | H10: Biopsies and cryostat sections | M10: =Lymph_subgroups_and_details!N7 -> 0.085808691 | N10: =Lymph_subgroups_and_details!M7 -> 0.034168738 | Q10: =AVERAGE($W$6:$W$7) -> 38446439 | R10: =sqrt(sumsq(stdev($W$6:$W$7), average($X$6:$X$7))) -> 17838078 | U10: 1170 | W10: =Q10*M10 -> 3299038.6 | X10: =sqrt(sumsq(M10*R10,N10*Q10)) -> 2017088.4 | Y10: see details in the subgroup and details tab
A11: Five studies | B11: Plasma cells | C11: Red marrow | F11: human | H11: morphlogical, flow cytometry | Q11: =AVERAGE($W$6:$W$7) -> 38446439 | R11: =sqrt(sumsq(stdev($W$6:$W$7), average($X$6:$X$7))) -> 17838078 | S11: =Lymph_subgroups_and_details!C24 -> 2543486329 | T11: =Lymph_subgroups_and_details!D24 -> 1276226483 | U11: 1170 | W11: =S11/U11 -> 2173919.9 | X11: =T11/S11*W11 -> 1090791.9 | Y11: see details in the subgroup and details tab
A12: Wang et al. 2020 + 5 studies | B12: T cells | C12: Spleen | F12: human | G12: healthy tissues from old patients | H12: Imaging Mass Cytometric Analysis + isolation, histology + | M12: =Lymph_subgroups_and_details!L82 -> 0.4 | N12: =Lymph_subgroups_and_details!M82 -> 0.030811028 | Q12: =3500/500^2/10*10^12 * Lymph_subgroups_and_details!$F$35 -> 1043000000 | R12: =Q12* 2/10 -> 208600000 | U12: 150 | W12: =Q12*M12 -> 417200000 | X12: =sqrt(sumsq(M12*R12,N12*Q12)) -> 89414483 | Y12: see details in the subgroup and details tab (density of spleenic cells according to Wang * 75% lymphocyte portion)
A13: Wang et al. 2020 + 5 studies | B13: B cells | C13: Spleen | F13: human | G13: healthy tissues from old patients | H13: Imaging Mass Cytometric Analysis + isolation, histology + | M13: =Lymph_subgroups_and_details!L83 -> 0.5 | N13: =Lymph_subgroups_and_details!M83 -> 0.027786818 | Q13: =3500/500^2/10*10^12 * Lymph_subgroups_and_details!$F$35 -> 1043000000 | R13: =Q13* 2/10 -> 208600000 | U13: 150 | W13: =Q13*M13 -> 521500000 | X13: =sqrt(sumsq(M13*R13,N13*Q13)) -> 1.0825168e+08 | Y13: see details in the subgroup and details tab (density of spleenic cells according to Wang * 75% lymphocyte portion)
A14: Wang et al. 2020 + 5 studies | B14: NK cells | C14: Spleen | F14: human | G14: healthy tissues from old patients | H14: Imaging Mass Cytometric Analysis + isolation, histology + | M14: =Lymph_subgroups_and_details!L84 -> 0.1 | N14: =Lymph_subgroups_and_details!M84 -> 0.008405188 | Q14: =3500/500^2/10*10^12 * Lymph_subgroups_and_details!$F$35 -> 1043000000 | R14: =Q14* 2/10 -> 208600000 | U14: 150 | W14: =Q14*M14 -> 104300000 | X14: =sqrt(sumsq(M14*R14,N14*Q14)) -> 22627264 | Y14: see details in the subgroup and details tab (density of spleenic cells according to Wang * 75% lymphocyte portion)
A15: Turesson 1976 + Wang et al. 2020 | B15: Plasma cells | C15: Spleen | F15: human | G15: healthy tissues from old patients | H15: Imaging Mass Cytometric Analysis + Ig markers | M15: 0.0044 | N15: =0.08% -> 0.0008 | Q15: =3500/500^2/10*10^12 -> 1400000000 | R15: =Q15* 2/10 -> 280000000 | U15: 150 | W15: =Q15*M15 -> 6160000 | X15: =sqrt(sumsq(M15*R15,N15*Q15)) -> 1664999.7
A16: Mei et al. 2015 + Wang et al. 2020 | B16: Plasma cells | C16: Spleen | F16: human | G16: healthy tissues from old patients | H16: Imaging Mass Cytometric Analysis + flow cytometry | M16: 0.0066 | Q16: =3500/500^2/10*10^12 * Lymph_subgroups_and_details!$F$35 -> 1043000000 | R16: =Q16* 2/10 -> 208600000 | U16: 150 | W16: =Q16*M16 -> 6883800 | X16: =sqrt(sumsq(M16*R16,N16*Q16)) -> 1376760
A17: Bar et al. 1988 | B17: Lymphocytes | C17: Lymph nodes | F17: human | G17: postmortem | H17: DNA content per g | W17: =average(2.2,2.2,4.7)/1000/(6.2*10^-12) -> 4.8924731e+08 | X17: =STDEV(2.2,2.2,4.7)/1000/(6.2*10^-12) -> 2.3280253e+08 | Y17: estimated from the DNA content per mg of samples of up until 1 day post mortem
A18: Rosse et al. 1971 | B18: Lymphocytes | C18: Lymph nodes | E18: Cervical | F18: guinea pig | H18: DNA content per g (hemocytometer) | W18: 1800000000
A19: Rosse et al. 1971 | B19: Lymphocytes | C19: Lymph nodes | E19: Mesenteric | F19: guinea pig | H19: DNA content per g (hemocytometer) | W19: 1400000000
A20: Rosse et al. 1971 | B20: Lymphocytes | C20: Lymph nodes | E20: Axillary | F20: guinea pig | H20: DNA content per g (hemocytometer) | W20: 1500000000
A21: Rosse et al. 1971 | B21: Lymphocytes | C21: Lymph nodes | E21: Popeliteal | F21: guinea pig | H21: DNA content per g (hemocytometer) | W21: 1300000000
A22: Everett et al. 1964 | B22: Lymphocytes | C22: Lymph nodes | E22: Mesenteric | F22: rat | H22: DNA content per g (colorimetric method) | W22: 1100000000
A23: Monden et al. 1959 | B23: Lymphocytes | C23: Lymph nodes | E23: Cervical | F23: rat | H23: DNA content per g (Schneider method) | W23: 1150000000
A24: Monden et al. 1959 | B24: Lymphocytes | C24: Lymph nodes | E24: Mesenteric | F24: rat | H24: DNA content per g (Schneider method) | W24: 1920000000
A25: Monden et al. 1959 | B25: Lymphocytes | C25: Lymph nodes | E25: Axillary | F25: rat | H25: DNA content per g (Schneider method) | W25: 1150000000
A26: Monden et al. 1959 | B26: Lymphocytes | C26: Lymph nodes | E26: Popeliteal | F26: rat | H26: DNA content per g (Schneider method) | W26: 1150000000
A27: Pabst and Trepel 1975 | B27: Lymphocytes | C27: Lymph nodes | E27: Paraaortal LN | F27: piglet | H27: DNA content per g (colorimetric method) | W27: 1030000000
A28: Away 1962 | B28: Lymphocytes | C28: Lymph nodes | E28: Mesenteric | F28: rat | H28: DNA content per g (hemocytometer) | W28: 2300000000
A29: Battaglia et al. 2003 & Backteman et al. 2012 | B29: T cells | C29: Lymph nodes | F29: human | H29: Flow cytometry | M29: =Lymph_subgroups_and_details!F91 -> 0.495125 | N29: =Lymph_subgroups_and_details!G91 -> 0.035927662 | Y29: values are relative to total cells in LN
A30: Battaglia et al. 2003 & Backteman et al. 2012 | B30: B cells | C30: Lymph nodes | F30: human | H30: Flow cytometry | M30: =Lymph_subgroups_and_details!F92 -> 0.342125 | N30: =Lymph_subgroups_and_details!G92 -> 0.02511567 | Y30: values are relative to total cells in LN
A31: Battaglia et al. 2003 & Backteman et al. 2012 | B31: NK cells | C31: Lymph nodes | F31: human | H31: Flow cytometry | M31: =Lymph_subgroups_and_details!F93 -> 0.01275 | N31: =Lymph_subgroups_and_details!G93 -> 0.0014168627 | Y31: values are relative to total cells in LN
A32: Turesson 1976 & Mei et al. 2015 | B32: Plasma cells | C32: Lymph nodes | F32: human | H32: Flow cytometry | M32: =Lymph_subgroups_and_details!D99 -> 0.0013076316 | N32: =Lymph_subgroups_and_details!E99 -> 0.0011795607 | Y32: values are relative to total cells in LN
A33: Marušić et al. 1988, Weerkamp et al. 2005, Westerman & Pabst 1992 | B33: T cells | C33: Thymus | F33: human | H33: Immunohistochemistry, cell suspension, flow cytometry | M33: 0.995 | O33: =Lymph_subgroups_and_details!$C$118 -> 2000000000 | P33: =Lymph_subgroups_and_details!$D$118 -> 1000000000 | S33: =O33*M33 -> 1990000000 | T33: =M33*P33 -> 995000000 | U33: =Tissues!$D$7 -> 25 | W33: =S33/U33 -> 79600000 | X33: =T33/U33 -> 39800000 | Y33: Data was scaraced. We combined two studies using regressionm. see detailed tab\
A34: Marušić et al. 1988, Weerkamp et al. 2005, Westerman & Pabst 1992 | B34: B cells | C34: Thymus | F34: human | H34: Immunohistochemistry, cell suspension, flow cytometry | M34: 0.005 | O34: =Lymph_subgroups_and_details!$C$118 -> 2000000000 | P34: =Lymph_subgroups_and_details!$D$118 -> 1000000000 | S34: =O34*M34 -> 10000000 | T34: =M34*P34 -> 5000000 | U34: =Tissues!$D$7 -> 25 | W34: =S34/U34 -> 400000 | X34: =T34/U34 -> 200000 | Y34: Data was scaraced. We combined two studies using regressionm. see detailed tab\
A35: Curry et al. 2000 | B35: Lymphocytes | C35: Liver | F35: human | H35: biopsy for lymphocyte isolation | W35: 10000000 | X35: 6000000 | Y35: biopsy mass range 110-345 mg, lymph number range 2.5-6\ x10^6
A36: Five studies | B36: T cells | C36: Liver | F36: human | H36: Flow cytometry, immunohistochemical | M36: =Lymph_subgroups_and_details!H133 -> 0.50381159 | N36: =Lymph_subgroups_and_details!I133 -> 0.098889821 | Y36: see details in the subgroup and details tab (density of spleenic cells according to Wang * 75% lymphocyte portion)
A37: Five studies | B37: B cells | C37: Liver | F37: human | H37: Flow cytometry, immunohistochemical | M37: =Lymph_subgroups_and_details!H134 -> 0.11851361 | N37: =Lymph_subgroups_and_details!I134 -> 0.035559296 | Y37: see details in the subgroup and details tab (density of spleenic cells according to Wang * 75% lymphocyte portion)
A38: Five studies | B38: NK cells | C38: Liver | F38: human | H38: Flow cytometry, immunohistochemical | M38: =Lymph_subgroups_and_details!H135 -> 0.3776748 | N38: =Lymph_subgroups_and_details!I135 -> 0.13352124 | Y38: see details in the subgroup and details tab (density of spleenic cells according to Wang * 75% lymphocyte portion)
A39: Purwar et al. 2011 | B39: T cells | C39: Lungs | F39: human | H39: Histology | I39: =500*500 -> 250000 | J39: 12 | W39: =9400*1000 -> 9400000 | X39: =200*1000 -> 200000 | Y39: study gives values in mm^3
A40: Carpenter et al. 2017 & Purwar et al. 2011 | B40: B cells | C40: Lungs | F40: human | H40: Flow cytometry | M40: =1/Lymph_subgroups_and_details!C139 -> 0.12675665 | N40: =Lymph_subgroups_and_details!D139/Lymph_subgroups_and_details!C139*M40 -> 0.025089215 | Q40: =W39 -> 9400000 | R40: =X39 -> 200000 | W40: =Q40*M40 -> 1191512.5 | X40: =sqrt(sumsq(M40*R40,N40*Q40)) -> 237197.27 | Y40: from T:B ratios
...

Sheet Lymph_subgroups_and_details
A1: Bone marrow
B3: Rego et al. 1988 (Biopsy) | C3: taken from >15 age group | E3: Thaler et al. 1989 (cryostat sections) | F3: Zhang et al. 2006 ( | H3: Clark et al. 1986 (biopsy)
C4: in lymphoid window | D4: std | F4: nucleated BM | G4: in lymphoid window | H4: sem | J4: Dogra et al. 2020 (FACS) | K4: Dogra IQR range | L4: mean before correction | M4: std | N4: mean
B5: T cells | C5: 0.348 | D5: 0.022135944 | F5: 0.09 | G5: 0.366 | H5: 0.023688077 | I5: 0.22 | L5: =average($C5/sum($C$5:$C$7),$G5/sum($G$5:$G$7),$I5/sum($I$5:$I$7)) -> 0.56725542 | M5: =STDEV($C5/sum($C$5:$C$7),$G5/sum($G$5:$G$7),$I5/sum($I$5:$I$7)) -> 0.094733285 | N5: =(1-$N$7)*L5/sum($L$5:$L$6) -> 0.53986472
B6: B cells | C6: 0.336 | D6: 0.018973666 | F6: 0.015 | G6: 0.253 | H6: 0.047376154 | I6: 0.11 | L6: =average($C6/sum($C$5:$C$7),$G6/sum($G$5:$G$7),$I6/sum($I$5:$I$7)) -> 0.3933185 | M6: =STDEV($C6/sum($C$5:$C$7),$G6/sum($G$5:$G$7),$I6/sum($I$5:$I$7)) -> 0.064498043 | N6: =(1-$N$7)*L6/sum($L$5:$L$6) -> 0.37432658
B7: NK cells | C7: 0.044 | D7: 0.0031622777 | G7: 0.038 | H7: 0.0053033009 | J7: 0.18 | K7: 9%-29% | L7: =average($C7/sum($C$5:$C$7),$G7/sum($G$5:$G$7),$I7/sum($I$5:$I$7)) -> 0.039426074 | M7: =STDEV($C7/sum($C$5:$C$7),$G7/sum($G$5:$G$7),$I7/sum($I$5:$I$7)) -> 0.034168738 | N7: =average(J7,L7, G7) -> 0.085808691
B8: monocytes | C8: 0.049 | D8: 0.0031622777
B9: CD33+/CD34- or CD34+/CD33- | C9: 0.14 | D9: 0.0063245553
C10: x10^9 estimated plasma cells | D10: lower | E10: upper | F10: trepel | G10: plasma/lymph | H10: new_estimate
B11: CD19+ | C11: 0.56397568 | D11: 0.33522604 | E11: 0.72148481 | F11: 50000000000 | G11: =C11*10^9/F11 -> 0.011279514 | H11: =G11*average(Lymphocytes!$T$6:$T$7) -> 1.1208243e+08
B12: CD19- | C12: 0.19988406 | D12: 0.13612947 | E12: 0.35737444 | F12: =F11 -> 50000000000 | G12: =C12*10^9/F12 -> 0.0039976813 | H12: =G12*average(Lymphocytes!$T$6:$T$7) -> 39724215
B13: total | C13: =sum(C11:C12) -> 0.76385974 | E13: {=sqrt(sumsq(E11:E12-C11:C12)) +C13} -> 0.98659803 | F13: =F12 -> 50000000000 | G13: =C13*10^9/F13 -> 0.015277195 | H13: =G13*average(Lymphocytes!$T$6:$T$7) -> 151806645
C14: mean | D14: sem
A15: Brynjolfsson et al. 2017 | B15: % PC out of BMNC | C15: 0.004 | D15: 0.0006
B16: total PC | C16: =C15*average(Lymphocytes!$O$6:$O$7) -> 4025000000 | D16: =sqrt(sumsq(D15*average(Lymphocytes!$O$6:$O$7),stdev(Lymphocytes!$O$6:$O$7)*C15)) -> 1557229611
A18: plasma | C18: mean | D18: sem | E18: method
B19: Steiner and Pearson 1966 | C19: =0.4%*average(Lymphocytes!$O$6:$O$7) -> 4025000000 | D19: =sqrt(sumsq(STDEV(Lymphocytes!$O$6:$O$7)*0.4%,0.03%*average(Lymphocytes!$O$6:$O$7))) -> 1466826000 | E19: morphplogical
B20: Mei et al. 2015 | C20: =H13 -> 151806645 | D20: =sqrt(sumsq((E13-C13)/C13,STDEV(Lymphocytes!$T$6:$T$7)/average(Lymphocytes!$T$6:$T$7)))*C20 -> 188130905 | E20: Flow cytometry
B21: Halliley et al. 2015 | C21: 2000000000 | D21: 950000000 | E21: Flow cytometry
B22: Brynjolfsson et al. 2017 | C22: =C16 -> 4025000000 | D22: =D16 -> 1557229611 | E22: Flow cytometry
B23: Terstappen et al. 1990 | C23: =0.25%*average(Lymphocytes!$O$6:$O$7) -> 2515625000 | D23: =0.02%*average(Lymphocytes!$O$6:$O$7) -> 201250000 | E23: Flow cytometry
B24: mean | C24: =average(C19:C23) -> 2543486329 | D24: =sqrt(sumsq(stdev(C19:C23)/sqrt(3),average(D19:D23))) -> 1276226483
A27: Spleen | B27: older studies | C27: Spleen | D27: cells/g | E27: cells/g sem | F27: lymph % | G27: lymp cells/g | H27: sem | I27: mass [g] | J27: total | M27: Dogra et al. 2020 | N27: median | O27: lower (25%) | P27: upper (75%)
C28: Li ZF et al. 2008 | D28: =G28/F29 -> 2.5522388e+08 | G28: =1.71*10^8 -> 171000000 | I28: 212 | J28: =I28*G28 -> 36252000000 | L28: =J28*0.2*10^-9 -> 7.2504 | M28: NK fraction | N28: 0.085069444 | O28: 0.034027778 | P28: 0.16770833
C29: Buckley et al. 1984 | D29: =(78.5%*1.1 + 1.8*21.5%)*10^8 -> 125050000 | F29: 0.67 | G29: =F29*D29 -> 83783500 | I29: 180 | J29: =I29*G29 -> 15081030000
C30: McMillan et al. 1972 | D30: =5.3*10^8 -> 530000000 | E30: =0.9*10^8 -> 90000000 | I30: 150 | J30: =I30*D30 -> 79500000000
C31: Longmire et al. 1973 | D31: =6.5*10^10/I31 -> 5.6034483e+08 | E31: =0.2*D31 -> 1.1206897e+08 | I31: 116
C32: Levin et al. 1975 | D32: =0.69*10^9 -> 690000000
C33: McMillan et al. 1974 | D33: =3.05/27.9*10^12/150 -> 7.2879331e+08
C34: Aggarwal et al. 2013 | F34: 0.82
D35: =average(D30:D33) -> 6.2728453e+08 | E35: =sqrt(sumsq(STDEV(D30:D33)/sqrt(3), average(E30:E31))) -> 1.1549611e+08 | F35: =AVERAGE(F28:F34) -> 0.745 | G35: =F35*D35 -> 467326978 | H35: =sqrt(sumsq(0.1*D35,E35*F35)) -> 106482546 | I35: 180 | J35: =I35*G35 -> 84118856044
B36: newer study | C36: Wang et al. 2020 | D36: =1.4*10^9 -> 1400000000 | I36: =round(stdev(I28:I30)/sqrt(2),-1) -> 20 | J36: =sqrt(sumsq(I36/I35,H35/G35))*J35 -> 21324311440
B44: Chu et al. 2014
B45: pixels/μm | C45: 2.88 | E45: depth [mu] | F45: 5
C46: heighest densities | D46: region | E46: per 10^-5 pixel area | F46: std | G46: per mu^2 | H46: per mu^3 | I46: per cm^3 | L46: =E47*C45^2/F45 -> 79.62624 | M46: =L46*10^7 -> 796262400
C47: T cells | D47: PALS | E47: 48 | F47: 15 | G47: =E47*$C$45^2/10^5 -> 0.003981312 | H47: =G47/$F$45 -> 0.0007962624 | I47: =H47*10^12 -> 796262400
C48: B cells | D48: MZ + part of RP | E48: 6.8 | F48: 0.8 | G48: =E48*$C$45^2/10^5 -> 0.0005640192 | H48: =G48/$F$45 -> 0.00011280384 | I48: =H48*10^12 -> 112803840 | M48: Gualdron-Lopez 2021 | O48: samples are not ordered
C49: Mac | D49: red pulp | E49: 7.5 | F49: 0.9 | G49: =E49*$C$45^2/10^5 -> 0.00062208 | H49: =G49/$F$45 -> 0.000124416 | I49: =H49*10^12 -> 124416000
M50: % of lymph out of nuceated cells | P50: RBC
F51: =AVERAGE(D52:F52) -> 0.71735537 | O51: sample 1 | P51: 0.56958447
...

Sheet GIT_dimensions
A1: GI dimensions | J1: Nylund et al. 2012 | M1: Nylund et al. 2012 and Cronin et al. 2012 for total thickness. Brandtzaeg and Baklien 1976 for mucosa thicknes (matching Ensary 1993 and similar to Nylund). Epithel & LP fraction from Ensary's colon. | P1: ratio from Nylund et al. , assuming the thickness mucsa and completing the total thickness. results similar to Nylund values
A2: section | B2: length[cm] | C2: length sem | D2: length reference | E2: diameter [cm] | F2: diameter sem [cm] | G2: diameter refrence | H2: total SA [cm^2] | I2: total SA sem | J2: total wall thickness [cm] | K2: tw sem [cm] | L2: mucosa [cm] | M2: mucosa sem [cm] | N2: epithel (surface + crypt) | O2: lamina propria | P2: submucosa [cm] | Q2: proper muscle [cm] | R2: total volume [cm3] | S2: total volume sem | T2: mucosal volume [cm3] | U2: mucosal volume sem | V2: epithel volume [cm3] | W2: epithel volume sem | X2: LP volume [cm3] | Y2: LP volume sem
A3: Doudenum | B3: 30 | C3: 5 | D3: Hounnou et al. 2002, Weaver et al. 1991, Snyder 1975 (for subdivision) | E3: 2.5 | F3: 0.5 | G3: Cronin et al. 2010 | H3: =B3*pi()*E3 -> 235.61945 | I3: =pi()*sqrt(sumsq(E3*C3,B3*F3)) -> 61.341558 | J3: =average(0.16,0.15) -> 0.155 | K3: =STDEV(0.16,0.15) -> 0.0070710678 | L3: 0.0765 | M3: 0.0053033009 | N3: =$L3*N$6/sum($N$6:$O$6) -> 0.04284 | O3: =$L3*O$6/sum($N$6:$O$6) -> 0.03366 | P3: =(J3-L3)/2 -> 0.03925 | Q3: =P3 -> 0.03925 | R3: =$B3*pi()*(($E3/2+$J3)^2-($E3/2)^2) -> 38.785317 | S3: =sqrt(sumsq($C3*pi()*(($E3/2+$J3)^2-($E3/2)^2), $B3*pi()*($F3*$J3), $B3*pi()*($E3*$K3 + 2*$J3*$K3))) -> 9.9319901 | T3: =$B3*pi()*(($E3/2+$L3)^2-($E3/2)^2) -> 18.576449 | U3: =sqrt(sumsq($C3*pi()*(($E3/2+$L3)^2-($E3/2)^2), $B3*pi()*($F3*$L3), $B3*pi()*($E3*$M3 + 2*$L3*$M3))) -> 4.9335493 | V3: =$B3*pi()*(($E3/2+$N3)^2-($E3/2)^2) -> 10.266907 | W3: =sqrt(sumsq($C3*pi()*(($E3/2+$N3)^2-($E3/2)^2), $B3*pi()*($F3*$N3))) -> 2.6464204 | X3: =$B3*pi()*(($E3/2 +N3+$O3)^2-($E3/2+N3)^2) -> 8.3095425 | Y3: =sqrt(sumsq($C3*pi()*(($E3/2+$N3+$O3)^2-($E3/2+$N3)^2), $B3*pi()*($F3*$O3))) -> 2.1057096
A4: Jejunum | B4: 210 | C4: 25 | D4: Hounnou et al. 2002, Weaver et al. 1991, Snyder 1975 (for subdivision) | E4: 2.5 | F4: 0.5 | G4: Cronin et al. 2010 | H4: =B4*pi()*E4 -> 1649.3361 | I4: =pi()*sqrt(sumsq(E4*C4,B4*F4)) -> 383.88218 | J4: =average(0.15) -> 0.15 | K4: =STDEV(0.15, 0.09) -> 0.042426407 | L4: 0.0765 | M4: 0.0053033009 | N4: =$L4*N$6/sum($N$6:$O$6) -> 0.04284 | O4: =$L4*O$6/sum($N$6:$O$6) -> 0.03366 | P4: =(J4-L4)/2 -> 0.03675 | Q4: =P4 -> 0.03675 | R4: =$B4*pi()*(($E4/2+J4)^2-($E4/2)^2) -> 262.24445 | S4: =sqrt(sumsq($C4*pi()*(($E4/2+$J4)^2-($E4/2)^2), $B4*pi()*($F4*$J4), $B4*pi()*($E4*$K4 + 2*$J4*$K4))) -> 97.801751 | T4: =$B4*pi()*(($E4/2+$L4)^2-($E4/2)^2) -> 130.03515 | U4: =sqrt(sumsq($C4*pi()*(($E4/2+$L4)^2-($E4/2)^2), $B4*pi()*($F4*$L4), $B4*pi()*($E4*$M4 + 2*$L4*$M4))) -> 31.025783 | V4: =$B4*pi()*(($E4/2+$N4)^2-($E4/2)^2) -> 71.868348 | W4: =sqrt(sumsq($C4*pi()*(($E4/2+$N4)^2-($E4/2)^2), $B4*pi()*($F4*$N4))) -> 16.519703 | X4: =$B4*pi()*(($E4/2 +N4+$O4)^2-($E4/2+N4)^2) -> 58.166798 | Y4: =sqrt(sumsq($C4*pi()*(($E4/2+$N4+$O4)^2-($E4/2+$N4)^2), $B4*pi()*($F4*$O4))) -> 13.085653
A5: Ilum | B5: 310 | C5: 40 | D5: Hounnou et al. 2002, Weaver et al. 1991, Snyder 1975 (for subdivision) | E5: 2 | F5: 0.3 | G5: Cronin et al. 2010 | H5: =B5*pi()*E5 -> 1947.7874 | I5: =pi()*sqrt(sumsq(E5*C5,B5*F5)) -> 385.39289 | J5: =average(0.16, 0.12) -> 0.14 | K5: =STDEV(0.16, 0.12) -> 0.028284271 | L5: 0.069 | M5: 0.0021105794 | N5: =$L5*N$6/sum($N$6:$O$6) -> 0.03864 | O5: =$L5*O$6/sum($N$6:$O$6) -> 0.03036 | P5: =(J5-L5)/2 -> 0.0355 | Q5: =P5 -> 0.0355 | R5: =$B5*pi()*(($E5/2+J5)^2-($E5/2)^2) -> 291.77856 | S5: =sqrt(sumsq($C5*pi()*(($E5/2+$J5)^2-($E5/2)^2), $B5*pi()*($F5*$J5), $B5*pi()*($E5*$K5 + 2*$J5*$K5))) -> 83.87462 | T5: =$B5*pi()*(($E5/2+$L5)^2-($E5/2)^2) -> 139.03404 | U5: =sqrt(sumsq($C5*pi()*(($E5/2+$L5)^2-($E5/2)^2), $B5*pi()*($F5*$L5), $B5*pi()*($E5*$M5 + 2*$L5*$M5))) -> 27.341567 | V5: =$B5*pi()*(($E5/2+$N5)^2-($E5/2)^2) -> 76.716579 | W5: =sqrt(sumsq($C5*pi()*(($E5/2+$N5)^2-($E5/2)^2), $B5*pi()*($F5*$N5))) -> 15.014609 | X5: =$B5*pi()*(($E5/2 +N5+$O5)^2-($E5/2+N5)^2) -> 62.317463 | Y5: =sqrt(sumsq($C5*pi()*(($E5/2+$N5+$O5)^2-($E5/2+$N5)^2), $B5*pi()*($F5*$O5))) -> 11.972383
A6: Colon | B6: 150 | C6: 20 | D6: Snyder et al. 1975, Helander & Fändriks, 2014, ICRP2002 | E6: 4.8 | F6: 1 | G6: Khashab et al. 2009 | H6: =B6*pi()*E6 -> 2261.9467 | I6: =pi()*sqrt(sumsq(E6*C6,B6*F6)) -> 559.48581 | J6: =average(0.15, 0.12) -> 0.135 | K6: =STDEV(0.15, 0.12) -> 0.021213203 | L6: 0.05 | M6: 0.0023570226 | N6: 0.028 | O6: 0.022 | P6: =(J6-L6)*3/8 -> 0.031875 | Q6: =(J6-L6)*5/8 -> 0.053125 | R6: =$B6*pi()*(($E6/2+J6)^2-($E6/2)^2) -> 313.95113 | S6: =sqrt(sumsq($C6*pi()*(($E6/2+$J6)^2-($E6/2)^2), $B6*pi()*($F6*$J6), $B6*pi()*($E6*$K6 + 2*$J6*$K6))) -> 91.47738 | T6: =$B6*pi()*(($E6/2+$L6)^2-($E6/2)^2) -> 114.27543 | U6: =sqrt(sumsq($C6*pi()*(($E6/2+$L6)^2-($E6/2)^2), $B6*pi()*($F6*$L6), $B6*pi()*($E6*$M6 + 2*$L6*$M6))) -> 28.582235 | V6: =$B6*pi()*(($E6/2+$N6)^2-($E6/2)^2) -> 63.703959 | W6: =sqrt(sumsq($C6*pi()*(($E6/2+$N6)^2-($E6/2)^2), $B6*pi()*($F6*$N6))) -> 15.692211 | X6: =$B6*pi()*(($E6/2 +N6+$O6)^2-($E6/2+N6)^2) -> 50.571474 | Y6: =sqrt(sumsq($C6*pi()*(($E6/2+$N6+$O6)^2-($E6/2+$N6)^2), $B6*pi()*($F6*$O6))) -> 12.367142
A7: Rectum | B7: 15 | C7: 2 | D7: Snyder et al. 1975, Helander & Fändriks, 2014, ICRP2002 | E7: 6.4 | F7: 1 | G7: Khashab et al. 2009 | H7: =B7*pi()*E7 -> 301.59289 | I7: =pi()*sqrt(sumsq(E7*C7,B7*F7)) -> 61.949148 | J7: 0.21 | K7: {=AVERAGE(K3:K6/J3:J6)*J7} -> 0.036100462 | L7: 0.05 | M7: 0.0023570226 | N7: =$L7*N$6/sum($N$6:$O$6) -> 0.028 | O7: =$L7*O$6/sum($N$6:$O$6) -> 0.022 | P7: =(J7-L7)*3/8 -> 0.06 | Q7: =(J7-L7)*5/8 -> 0.1 | R7: =$B7*pi()*(($E7/2+J7)^2-($E7/2)^2) -> 65.412671 | S7: =sqrt(sumsq($C7*pi()*(($E7/2+$J7)^2-($E7/2)^2), $B7*pi()*($F7*$J7), $B7*pi()*($E7*$K7 + 2*$J7*$K7))) -> 17.567264 | T7: =$B7*pi()*(($E7/2+$L7)^2-($E7/2)^2) -> 15.197454 | U7: =sqrt(sumsq($C7*pi()*(($E7/2+$L7)^2-($E7/2)^2), $B7*pi()*($F7*$L7), $B7*pi()*($E7*$M7 + 2*$L7*$M7))) -> 3.1904378 | V7: =$B7*pi()*(($E7/2+$N7)^2-($E7/2)^2) -> 8.4815462 | W7: =sqrt(sumsq($C7*pi()*(($E7/2+$N7)^2-($E7/2)^2), $B7*pi()*($F7*$N7))) -> 1.7377778 | X7: =$B7*pi()*(($E7/2 +N7+$O7)^2-($E7/2+N7)^2) -> 6.7159083 | Y7: =sqrt(sumsq($C7*pi()*(($E7/2+$N7+$O7)^2-($E7/2+$N7)^2), $B7*pi()*($F7*$O7))) -> 1.3699046
A8: totals
A9: SI | H9: =sum(H3:H5) -> 3832.743 | I9: =sqrt(sumsq(I3:I5)) -> 547.40843 | R9: =sum(R3:R5) -> 592.80832 | S9: =sqrt(sumsq(S3:S5)) -> 129.22375 | T9: =sum(T3:T5) -> 287.64564 | U9: =sqrt(sumsq(U3:U5)) -> 41.647334 | V9: =sum(V3:V5) -> 158.85183 | W9: =sqrt(sumsq(W3:W5)) -> 22.479827 | X9: =sum(X3:X5) -> 128.7938 | Y9: =sqrt(sumsq(Y3:Y5)) -> 17.860747
A10: Colon | H10: =sum(H6:H7) -> 2563.5396 | I10: =SQRT(SUMSQ(I6:I7)) -> 562.90503 | R10: =sum(R6:R7) -> 379.36381 | S10: =SQRT(SUMSQ(S6:S7)) -> 93.148912 | T10: =sum(T6:T7) -> 129.47289 | U10: =SQRT(SUMSQ(U6:U7)) -> 28.759747 | V10: =sum(V6:V7) -> 72.185505 | W10: =SQRT(SUMSQ(W6:W7)) -> 15.78814 | X10: =sum(X6:X7) -> 57.287382 | Y10: =SQRT(SUMSQ(Y6:Y7)) -> 12.442782
A11: (including rectum)
A16: PP mass [g] | B16: 20 | C16: Trepel
A17: Intestine specific gravity | B17: 1.04 | C17: Snyder et al. 1975

Sheet Loyfer_data
A1: tissue | B1: Adipose_STL001 | C1: Adipose_STL002 | D1: Adipose_STL003 | E1: Aorta_STL002 | F1: Aorta_STL003 | G1: Bladder_STL001 | H1: Brain-Astrocyte-741 | I1: Brain-Brodmann11-681 | J1: Brain-Brodmann11-731 | K1: Brain-Cerebellum-724 | L1: Brain-Cerebellum-749 | M1: Brain-Cerebellum-761 | N1: Brain-Cerebellum-898 | O1: Brain-Cortex-762 | P1: Brain-Cortex-869 | Q1: Brain-Germinal-Matrix-821 | R1: Brain-Hippocampus-794 | S1: Brain-Insular-Cortex-837 | T1: Brain-MGE-798 | U1: Brain-MGE-843 | V1: Brain-MGE-882 | W1: Breast-Fibroblast-838 | X1: Breast-Fibroblast-917 | Y1: Breast-Luminal-Epithel-782 | Z1: Breast-Luminal-Epithel-873 | AA1: Breast-Mammary-Epithel-735 | AB1: mammary_epithelial_cell_714 | AC1: mammary_epithelial_cell_715 | AD1: Breast-Myoepithel-694 | AE1: Breast-Myoepithel-770 | AF1: Breast-Myoepithel-771 | AG1: Breast-Myoepithel-778 | AH1: Breast-Progenitor-Enriched-927 | AI1: esophagus_squamous_epithelium_903 | AJ1: transverse_colon_891 | AK1: transverse_colon_912 | AL1: Sigmoid_Colon_STL001 | AM1: Sigmoid_Colon_STL003 | AN1: Esophagus_STL002 | AO1: Esophagus_STL003 | AP1: esophagus_muscularis_mucosa_926 | AQ1: esophagus_squamous_epithelium_925 | AR1: fibroblast_of_arm_642 | AS1: fibroblast_of_arm_643 | AT1: Gastric_STL001 | AU1: Gastric_STL002 | AV1: Gastric_STL003 | AW1: gastroesophageal_sphincter_904 | AX1: gastroesophageal_sphincter_924 | AY1: hepatocyte_899 | AZ1: Liver_STL011 | BA1: right_lobe_of_liver_886 | BB1: right_lobe_of_liver_887 | BC1: Lung_STL001 | BD1: Lung_STL002 | BE1: upper_lobe_of_left_lung_893 | BF1: upper_lobe_of_left_lung_913 | BG1: ovary_895 | BH1: ovary_922 | BI1: Ovary_STL002 | BJ1: body_of_pancreas_897 | BK1: body_of_pancreas_930 | BL1: Pancreas_STL002 | BM1: Pancreas_STL003 | BN1: Pancreas-Islet-695 | BO1: Penis-Skin-Fibroblast-926 | BP1: Penis-Skin-Keratinocyte-901 | BQ1: Penis-Skin-Melanocyte-696 | BR1: prostate_gland_919 | BS1: Psoas_Muscle_STL001 | BT1: Psoas_Muscle_STL002 | BU1: Psoas_Muscle_STL003 | BV1: Right_Atrium_STL003 | BW1: skeletal_muscle_myoblast_450 | BX1: skeletal_muscle_myoblast_451 | BY1: Skin-Nevus-739 | BZ1: lower_leg_skin_888 | CA1: lower_leg_skin_927 | CB1: suprapubic_skin_892 | CC1: Small_Intestine_STL001 | CD1: Small_Intestine_STL002 | CE1: Small_Intestine_STL003 | CF1: smooth_muscle_884 | CG1: smooth_muscle_885 | CH1: smooth_muscle_928 | CI1: smooth_muscle_929 | CJ1: stomach_894 | CK1: stomach_907 | CL1: thyroid_gland_900 | CM1: thyroid_gland_908 | CN1: tibial_nerve_911 | CO1: tibial_nerve_916 | CP1: heart_left_ventricle_896 | CQ1: heart_left_ventricle_918 | CR1: Left_Ventricle_STL001 | CS1: Left_Ventricle_STL003 | CT1: Right_Ventricle_STL001 | CU1: Right_Ventricle_STL003
A2: Adipocytes | B2: 0.420491 | C2: 0.415985 | D2: 0.247489
A3: Prostate-Ep | G3: 7.2e-05
A4: Bladder-Ep | G4: 0.065795
A5: Blood-B | B5: 0.107281 | C5: 0.000972 | D5: 0.006672 | E5: 0 | F5: 0 | G5: 0.004536 | H5: 0.000593 | I5: 0.008075 | J5: 0 | K5: 0 | L5: 0.004407 | M5: 0.007731 | N5: 0.002657 | O5: 0.009076 | P5: 0.002027 | Q5: 0.044438 | R5: 0 | S5: 0 | T5: 0.031532 | U5: 0.003495 | V5: 0.005615 | W5: 0.00358 | X5: 0.009953 | Y5: 0.005381 | Z5: 0 | AA5: 0.010243 | AB5: 0.007189 | AC5: 0.003535 | AD5: 0 | AE5: 0 | AF5: 0 | AG5: 0 | AH5: 0.037105 | AI5: 0.076715 | AJ5: 0 | AK5: 0.027343 | AL5: 0.163664 | AM5: 0 | AN5: 0.011704 | AO5: 0.009928 | AP5: 0 | AQ5: 0.02745 | AR5: 0.003635 | AS5: 0 | AT5: 0.021861 | AU5: 0 | AV5: 0.007468 | AW5: 0 | AX5: 0 | AY5: 0.000266 | AZ5: 0.001792 | BA5: 0.001534 | BB5: 0.004001 | BC5: 0.009449 | BD5: 0 | BE5: 0 | BF5: 0 | BG5: 0.019167 | BH5: 0.005165 | BI5: 0.002859 | BJ5: 0.002096 | BK5: 0 | BL5: 0.007011 | BM5: 0.018836 | BN5: 0.011676 | BO5: 0.002629 | BP5: 0.077193 | BQ5: 0.037654 | BR5: 0 | BS5: 0.008638 | BT5: 0.002669 | BU5: 0.006921 | BV5: 0 | BW5: 0.007239 | BX5: 0.00265 | BY5: 0.014768 | BZ5: 0 | CA5: 0 | CB5: 0.009051 | CC5: 0.0429 | CD5: 0.038016 | CE5: 0.01434 | CF5: 0.045175 | CG5: 0.050133 | CH5: 0.004732 | CI5: 0.019476 | CJ5: 0 | CK5: 0.006273 | CL5: 0.004048 | CM5: 0.001673 | CN5: 0 | CO5: 0.000654 | CP5: 0 | CQ5: 0.004494 | CR5: 0.017128 | CS5: 0 | CT5: 0 | CU5: 9.6e-05
A6: Blood-Granul | B6: 0.001935 | C6: 0.167785 | D6: 0.349794 | E6: 0 | F6: 0 | G6: 0 | H6: 0.045857 | I6: 0.033499 | J6: 0.012639 | K6: 0.039647 | L6: 0.032382 | M6: 0.023252 | N6: 0.009382 | O6: 0.013051 | P6: 0 | Q6: 0.232508 | R6: 0.034556 | S6: 0.041277 | T6: 0.19487 | U6: 0.019278 | V6: 0.016597 | W6: 0.04945 | X6: 0.008764 | Y6: 0 | Z6: 0.017465 | AA6: 0.082709 | AB6: 0 | AC6: 0 | AD6: 0.032194 | AE6: 0 | AF6: 0 | AG6: 0 | AH6: 0.072853 | AI6: 0.005327 | AJ6: 0 | AK6: 0 | AL6: 0.001191 | AM6: 0.005128 | AN6: 0 | AO6: 0.007462 | AP6: 0.030474 | AQ6: 0.086517 | AR6: 0.01247 | AS6: 0.004283 | AT6: 0.055399 | AU6: 0.00109 | AV6: 0.038614 | AW6: 0.025858 | AX6: 0.008772 | AY6: 0.048186 | AZ6: 0.021041 | BA6: 0.021975 | BB6: 0.058312 | BC6: 0.47079 | BD6: 0.076548 | BE6: 0.052477 | BF6: 0.083524 | BG6: 0.019151 | BH6: 0.024539 | BI6: 0.011862 | BJ6: 0.012714 | BK6: 0.032677 | BL6: 0.004239 | BM6: 0 | BN6: 0.054692 | BO6: 0.002294 | BP6: 0.211293 | BQ6: 0.027107 | BR6: 0.03385 | BS6: 0 | BT6: 0 | BU6: 0 | BV6: 0.031661 | BW6: 0 | BX6: 0 | BY6: 0.070088 | BZ6: 0.013694 | CA6: 0.007979 | CB6: 0.032105 | CC6: 0.001873 | CD6: 0.012292 | CE6: 0.001729 | CF6: 0.08418 | CG6: 0.070894 | CH6: 0.044191 | CI6: 0.032796 | CJ6: 0.071441 | CK6: 0.006 | CL6: 0.005954 | CM6: 0.012189 | CN6: 0.004085 | CO6: 0.004647 | CP6: 0.023971 | CQ6: 0.01374 | CR6: 0.005815 | CS6: 0.004277 | CT6: 0 | CU6: 0.015463
A7: Blood-Mono+Macro | B7: 0.011987 | C7: 0.032696 | D7: 0.084398 | E7: 0.014496 | F7: 0.009112 | G7: 0.075811 | H7: 0 | I7: 0.037422 | J7: 0.064175 | K7: 0 | L7: 0.046212 | M7: 0 | N7: 0 | O7: 0.005629 | P7: 0 | Q7: 0 | R7: 0.117902 | S7: 0.092262 | T7: 0.043076 | U7: 0 | V7: 0 | W7: 0.001677 | X7: 0 | Y7: 0 | Z7: 0 | AA7: 0.058383 | AB7: 0.01239 | AC7: 0.001568 | AD7: 0 | AE7: 0 | AF7: 0 | AG7: 0 | AH7: 0.043966 | AI7: 0.144565 | AJ7: 0.034503 | AK7: 0.102208 | AL7: 0.072113 | AM7: 0.042265 | AN7: 0.035007 | AO7: 0.054507 | AP7: 0.21306 | AQ7: 0.054668 | AR7: 0.008969 | AS7: 0.023327 | AT7: 0.08215 | AU7: 0.018732 | AV7: 0.051719 | AW7: 0.115652 | AX7: 0.065382 | AY7: 0.055991 | AZ7: 0.046507 | BA7: 0.108222 | BB7: 0.111444 | BC7: 0.152242 | BD7: 0.163465 | BE7: 0.130745 | BF7: 0.149964 | BG7: 0.076972 | BH7: 0.061244 | BI7: 0.105651 | BJ7: 0.056357 | BK7: 0.119448 | BL7: 0.013799 | BM7: 0.03032 | BN7: 0 | BO7: 0.03635 | BP7: 0.104507 | BQ7: 0.1098 | BR7: 0.125449 | BS7: 0 | BT7: 0 | BU7: 0 | BV7: 0.072286 | BW7: 0 | BX7: 0 | BY7: 0.175014 | BZ7: 0.163544 | CA7: 0.144475 | CB7: 0.204966 | CC7: 0.105579 | CD7: 0.060199 | CE7: 0.020104 | CF7: 0.118018 | CG7: 0.079562 | CH7: 0.045088 | CI7: 0.060304 | CJ7: 0.084599 | CK7: 0.017447 | CL7: 0.031962 | CM7: 0.038138 | CN7: 0.156289 | CO7: 0.228514 | CP7: 0.06598 | CQ7: 0.055734 | CR7: 0.053714 | CS7: 0.045961 | CT7: 0.051958 | CU7: 0.07373
A8: Blood-NK | B8: 0.013346 | C8: 0 | D8: 0.002719 | E8: 0 | F8: 0 | G8: 0.005077 | H8: 0 | I8: 0 | J8: 0.005102 | K8: 0 | L8: 0 | M8: 0.00682 | N8: 0 | O8: 0 | P8: 0 | Q8: 0 | R8: 0 | S8: 0.014792 | T8: 0.000737 | U8: 0 | V8: 0 | W8: 0 | X8: 0 | Y8: 0.004245 | Z8: 0 | AA8: 0.012543 | AB8: 0.007894 | AC8: 0.021819 | AD8: 0.005542 | AE8: 0 | AF8: 0.003054 | AG8: 0.002021 | AH8: 0.004621 | AI8: 0.004456 | AJ8: 0 | AK8: 0 | AL8: 0.000349 | AM8: 0 | AN8: 0 | AO8: 0 | AP8: 0.00621 | AQ8: 0.006775 | AR8: 0 | AS8: 0 | AT8: 0.006727 | AU8: 0 | AV8: 0.001054 | AW8: 0 | AX8: 0.030642 | AY8: 0.015033 | AZ8: 0.011353 | BA8: 0 | BB8: 0.017361 | BC8: 0.018051 | BD8: 0.021604 | BE8: 0.027768 | BF8: 0.007463 | BG8: 0 | BH8: 0 | BI8: 0 | BJ8: 0 | BK8: 0 | BL8: 0 | BM8: 0.001944 | BN8: 0.017798 | BO8: 0.009465 | BP8: 0.059214 | BQ8: 0.02107 | BR8: 0 | BS8: 0 | BT8: 0 | BU8: 0 | BV8: 3e-05 | BW8: 0 | BX8: 0 | BY8: 0.019141 | BZ8: 0.000238 | CA8: 0.004518 | CB8: 0.007259 | CC8: 0.015021 | CD8: 0 | CE8: 0.000118 | CF8: 0.028959 | CG8: 0.00878 | CH8: 0.048119 | CI8: 0.023165 | CJ8: 0 | CK8: 0.002191 | CL8: 0.001741 | CM8: 0 | CN8: 0.014247 | CO8: 0.006492 | CP8: 0.001738 | CQ8: 0.0009 | CR8: 0.003756 | CS8: 0.002843 | CT8: 0.00194 | CU8: 0.001491
A9: Blood-T | B9: 0.117096 | C9: 0.058827 | D9: 0.029513 | E9: 0 | F9: 0 | G9: 0.014539 | H9: 0.023313 | I9: 0.01706 | J9: 0.000127 | K9: 0.028595 | L9: 0.009605 | M9: 0.011821 | N9: 0 | O9: 0 | P9: 0.011046 | Q9: 0.04556 | R9: 0.016629 | S9: 0.024609 | T9: 0.045318 | U9: 0.015895 | V9: 0.00881 | W9: 0 | X9: 0.082245 | Y9: 0.008654 | Z9: 0.012163 | AA9: 0.033971 | AB9: 0.006971 | AC9: 0 | AD9: 0 | AE9: 0 | AF9: 0 | AG9: 0 | AH9: 0 | AI9: 0.165786 | AJ9: 0.064013 | AK9: 0.028839 | AL9: 0.177683 | AM9: 0.03065 | AN9: 0.162118 | AO9: 0.101257 | AP9: 0.038298 | AQ9: 0.055177 | AR9: 0.011066 | AS9: 0.012947 | AT9: 0.084495 | AU9: 0.098582 | AV9: 0.039916 | AW9: 0.058133 | AX9: 0 | AY9: 0.000172 | AZ9: 0.035161 | BA9: 0.102073 | BB9: 0.05833 | BC9: 0.037513 | BD9: 0.064381 | BE9: 0.064665 | BF9: 0.058706 | BG9: 0 | BH9: 0.008696 | BI9: 0.014132 | BJ9: 0.041388 | BK9: 0.038657 | BL9: 0.000467 | BM9: 0.048603 | BN9: 0 | BO9: 0.019327 | BP9: 0.043604 | BQ9: 0.015623 | BR9: 0.042763 | BS9: 0 | BT9: 0 | BU9: 0 | BV9: 0 | BW9: 0 | BX9: 0 | BY9: 0.034414 | BZ9: 0.039898 | CA9: 0.054676 | CB9: 0.054275 | CC9: 0.123596 | CD9: 0.207884 | CE9: 0.066891 | CF9: 0.049115 | CG9: 0.048688 | CH9: 0 | CI9: 0 | CJ9: 0.106674 | CK9: 0.078803 | CL9: 0.004255 | CM9: 0.053342 | CN9: 0.028891 | CO9: 0.006263 | CP9: 0 | CQ9: 0 | CR9: 0.048307 | CS9: 0 | CT9: 0 | CU9: 0.005297
A10: Breast-Basal-Ep | W10: 0.025654 | X10: 0.00668 | Y10: 0.016831 | Z10: 0 | AA10: 0.34868 | AB10: 0.638575 | AC10: 0.62009 | AD10: 0.962264 | AE10: 1 | AF10: 0.992811 | AG10: 0.997979 | AH10: 0.029823
A11: Breast-Luminal-Ep | W11: 0.016253 | X11: 0 | Y11: 0.930558 | Z11: 0.957892 | AA11: 0.375791 | AB11: 0.206542 | AC11: 0.212841 | AD11: 0 | AE11: 0 | AF11: 0 | AG11: 0 | AH11: 0.044789
